Workbook
Name table: 'wip-include_channels_wip'!$B$1:$J$6113

Sheet wip-include_channels_wip
A1: File | B1: ChannelID | C1: Keep | D1: DisplayName | E1: ProgrammeCount | F1: Excluded | G1: Duplicate | H1: HD | I1: Network | J1: FirstWord
B2: 10.au | C2: Y | D2: 1 | E2: 0 | F2: FALSE | G2: =IF(COUNTIF($B:$B,B2)=1,"Unique","Duplicate") -> Unique | H2: =IF(ISNUMBER(SEARCH("HD",D2)), IF(COUNTIF($D:$D,SUBSTITUTE(D2," HD",""))>0,"Has non-HD match","HD only"), IF(COUNTIF($D:$D,D2&" HD")>0,"Has HD match","Non-HD only") ) -> Non-HD only | I2: =IFERROR(LOOKUP(2,1/(ISNUMBER(SEARCH(Sheet1!$A$2:$A$100,B2))),Sheet1!$A$2:$A$100),"") -> 0 | J2: =LEFT(B2,FIND(" ",B2&" ")-1) -> 10.au
B3: 11.au | C3: Y | D3: 1 | E3: 0 | F3: FALSE | G3: =IF(COUNTIF($B:$B,B3)=1,"Unique","Duplicate") -> Unique | H3: =IF(ISNUMBER(SEARCH("HD",D3)), IF(COUNTIF($D:$D,SUBSTITUTE(D3," HD",""))>0,"Has non-HD match","HD only"), IF(COUNTIF($D:$D,D3&" HD")>0,"Has HD match","Non-HD only") ) -> Non-HD only | I3: =IFERROR(LOOKUP(2,1/(ISNUMBER(SEARCH(Sheet1!$A$2:$A$100,B3))),Sheet1!$A$2:$A$100),"") -> 0 | J3: =LEFT(B3,FIND(" ",B3&" ")-1) -> 11.au
B4: 7.au | C4: Y | D4: 7 | E4: 0 | F4: FALSE | G4: =IF(COUNTIF($B:$B,B4)=1,"Unique","Duplicate") -> Unique | H4: =IF(ISNUMBER(SEARCH("HD",D4)), IF(COUNTIF($D:$D,SUBSTITUTE(D4," HD",""))>0,"Has non-HD match","HD only"), IF(COUNTIF($D:$D,D4&" HD")>0,"Has HD match","Non-HD only") ) -> Non-HD only | I4: =IFERROR(LOOKUP(2,1/(ISNUMBER(SEARCH(Sheet1!$A$2:$A$100,B4))),Sheet1!$A$2:$A$100),"") -> 0 | J4: =LEFT(B4,FIND(" ",B4&" ")-1) -> 7.au
B5: 9.au | C5: Y | D5: 9 | E5: 0 | F5: FALSE | G5: =IF(COUNTIF($B:$B,B5)=1,"Unique","Duplicate") -> Unique | H5: =IF(ISNUMBER(SEARCH("HD",D5)), IF(COUNTIF($D:$D,SUBSTITUTE(D5," HD",""))>0,"Has non-HD match","HD only"), IF(COUNTIF($D:$D,D5&" HD")>0,"Has HD match","Non-HD only") ) -> Non-HD only | I5: =IFERROR(LOOKUP(2,1/(ISNUMBER(SEARCH(Sheet1!$A$2:$A$100,B5))),Sheet1!$A$2:$A$100),"") -> 0 | J5: =LEFT(B5,FIND(" ",B5&" ")-1) -> 9.au
B6: Adult Swim - East.ca | C6: Y | D6: A | E6: 197 | F6: TRUE | G6: =IF(COUNTIF($B:$B,B6)=1,"Unique","Duplicate") -> Unique | H6: =IF(ISNUMBER(SEARCH("HD",D6)), IF(COUNTIF($D:$D,SUBSTITUTE(D6," HD",""))>0,"Has non-HD match","HD only"), IF(COUNTIF($D:$D,D6&" HD")>0,"Has HD match","Non-HD only") ) -> Non-HD only | I6: =IFERROR(LOOKUP(2,1/(ISNUMBER(SEARCH(Sheet1!$A$2:$A$100,B6))),Sheet1!$A$2:$A$100),"") -> 0 | J6: =LEFT(B6,FIND(" ",B6&" ")-1) -> Adult
B7: Adult Swim.ca | C7: Y | D7: A | E7: 105 | F7: FALSE | G7: =IF(COUNTIF($B:$B,B7)=1,"Unique","Duplicate") -> Unique | H7: =IF(ISNUMBER(SEARCH("HD",D7)), IF(COUNTIF($D:$D,SUBSTITUTE(D7," HD",""))>0,"Has non-HD match","HD only"), IF(COUNTIF($D:$D,D7&" HD")>0,"Has HD match","Non-HD only") ) -> Non-HD only | I7: =IFERROR(LOOKUP(2,1/(ISNUMBER(SEARCH(Sheet1!$A$2:$A$100,B7))),Sheet1!$A$2:$A$100),"") -> 0 | J7: =LEFT(B7,FIND(" ",B7&" ")-1) -> Adult
B8: Adult Swim.us | C8: Y | D8: A | E8: 185 | F8: FALSE | G8: =IF(COUNTIF($B:$B,B8)=1,"Unique","Duplicate") -> Unique | H8: =IF(ISNUMBER(SEARCH("HD",D8)), IF(COUNTIF($D:$D,SUBSTITUTE(D8," HD",""))>0,"Has non-HD match","HD only"), IF(COUNTIF($D:$D,D8&" HD")>0,"Has HD match","Non-HD only") ) -> Non-HD only | I8: =IFERROR(LOOKUP(2,1/(ISNUMBER(SEARCH(Sheet1!$A$2:$A$100,B8))),Sheet1!$A$2:$A$100),"") -> 0 | J8: =LEFT(B8,FIND(" ",B8&" ")-1) -> Adult
B9: Animal Planet (East).us | C9: Y | D9: A | E9: 53 | F9: FALSE | G9: =IF(COUNTIF($B:$B,B9)=1,"Unique","Duplicate") -> Unique | H9: =IF(ISNUMBER(SEARCH("HD",D9)), IF(COUNTIF($D:$D,SUBSTITUTE(D9," HD",""))>0,"Has non-HD match","HD only"), IF(COUNTIF($D:$D,D9&" HD")>0,"Has HD match","Non-HD only") ) -> Non-HD only | I9: =IFERROR(LOOKUP(2,1/(ISNUMBER(SEARCH(Sheet1!$A$2:$A$100,B9))),Sheet1!$A$2:$A$100),"") -> Animal | J9: =LEFT(B9,FIND(" ",B9&" ")-1) -> Animal
A10: open-epg-au.xml | B10: Animal Planet / ANI.au | C10: Y | D10: A | E10: 60 | F10: FALSE | G10: =IF(COUNTIF($B:$B,B10)=1,"Unique","Duplicate") -> Unique | H10: =IF(ISNUMBER(SEARCH("HD",D10)), IF(COUNTIF($D:$D,SUBSTITUTE(D10," HD",""))>0,"Has non-HD match","HD only"), IF(COUNTIF($D:$D,D10&" HD")>0,"Has HD match","Non-HD only") ) -> Non-HD only | I10: =IFERROR(LOOKUP(2,1/(ISNUMBER(SEARCH(Sheet1!$A$2:$A$100,B10))),Sheet1!$A$2:$A$100),"") -> Animal | J10: =LEFT(B10,FIND(" ",B10&" ")-1) -> Animal
B11: Animal Planet +1.uk | C11: Y | D11: A | E11: 119 | F11: FALSE | G11: =IF(COUNTIF($B:$B,B11)=1,"Unique","Duplicate") -> Unique | H11: =IF(ISNUMBER(SEARCH("HD",D11)), IF(COUNTIF($D:$D,SUBSTITUTE(D11," HD",""))>0,"Has non-HD match","HD only"), IF(COUNTIF($D:$D,D11&" HD")>0,"Has HD match","Non-HD only") ) -> Non-HD only | I11: =IFERROR(LOOKUP(2,1/(ISNUMBER(SEARCH(Sheet1!$A$2:$A$100,B11))),Sheet1!$A$2:$A$100),"") -> Animal | J11: =LEFT(B11,FIND(" ",B11&" ")-1) -> Animal
B12: Animal Planet ANI.au | C12: Y | D12: A | E12: 59 | F12: FALSE | G12: =IF(COUNTIF($B:$B,B12)=1,"Unique","Duplicate") -> Unique | H12: =IF(ISNUMBER(SEARCH("HD",D12)), IF(COUNTIF($D:$D,SUBSTITUTE(D12," HD",""))>0,"Has non-HD match","HD only"), IF(COUNTIF($D:$D,D12&" HD")>0,"Has HD match","Non-HD only") ) -> Non-HD only | I12: =IFERROR(LOOKUP(2,1/(ISNUMBER(SEARCH(Sheet1!$A$2:$A$100,B12))),Sheet1!$A$2:$A$100),"") -> Animal | J12: =LEFT(B12,FIND(" ",B12&" ")-1) -> Animal
B13: AandE Canada.ca | C13: Y | D13: A | E13: 144 | F13: FALSE | G13: =IF(COUNTIF($B:$B,B13)=1,"Unique","Duplicate") -> Unique | H13: =IF(ISNUMBER(SEARCH("HD",D13)), IF(COUNTIF($D:$D,SUBSTITUTE(D13," HD",""))>0,"Has non-HD match","HD only"), IF(COUNTIF($D:$D,D13&" HD")>0,"Has HD match","Non-HD only") ) -> Non-HD only | I13: =IFERROR(LOOKUP(2,1/(ISNUMBER(SEARCH(Sheet1!$A$2:$A$100,B13))),Sheet1!$A$2:$A$100),"") -> AandE | J13: =LEFT(B13,FIND(" ",B13&" ")-1) -> AandE
B14: AandE Network (East).us | C14: Y | D14: A | E14: 83 | F14: FALSE | G14: =IF(COUNTIF($B:$B,B14)=1,"Unique","Duplicate") -> Unique | H14: =IF(ISNUMBER(SEARCH("HD",D14)), IF(COUNTIF($D:$D,SUBSTITUTE(D14," HD",""))>0,"Has non-HD match","HD only"), IF(COUNTIF($D:$D,D14&" HD")>0,"Has HD match","Non-HD only") ) -> Non-HD only | I14: =IFERROR(LOOKUP(2,1/(ISNUMBER(SEARCH(Sheet1!$A$2:$A$100,B14))),Sheet1!$A$2:$A$100),"") -> AandE | J14: =LEFT(B14,FIND(" ",B14&" ")-1) -> AandE
A15: open-epg-au.xml | B15: AandE Network Canada.ca | C15: Y | D15: A | E15: 81 | F15: FALSE | G15: =IF(COUNTIF($B:$B,B15)=1,"Unique","Duplicate") -> Unique | H15: =IF(ISNUMBER(SEARCH("HD",D15)), IF(COUNTIF($D:$D,SUBSTITUTE(D15," HD",""))>0,"Has non-HD match","HD only"), IF(COUNTIF($D:$D,D15&" HD")>0,"Has HD match","Non-HD only") ) -> Non-HD only | I15: =IFERROR(LOOKUP(2,1/(ISNUMBER(SEARCH(Sheet1!$A$2:$A$100,B15))),Sheet1!$A$2:$A$100),"") -> AandE | J15: =LEFT(B15,FIND(" ",B15&" ")-1) -> AandE
B16: AandE US - Pacific Feed (132).us | C16: Y | D16: A | E16: 109 | F16: FALSE | G16: =IF(COUNTIF($B:$B,B16)=1,"Unique","Duplicate") -> Unique | H16: =IF(ISNUMBER(SEARCH("HD",D16)), IF(COUNTIF($D:$D,SUBSTITUTE(D16," HD",""))>0,"Has non-HD match","HD only"), IF(COUNTIF($D:$D,D16&" HD")>0,"Has HD match","Non-HD only") ) -> Non-HD only | I16: =IFERROR(LOOKUP(2,1/(ISNUMBER(SEARCH(Sheet1!$A$2:$A$100,B16))),Sheet1!$A$2:$A$100),"") -> AandE | J16: =LEFT(B16,FIND(" ",B16&" ")-1) -> AandE
B17: AAndE.us | C17: Y | D17: A | E17: 109 | F17: FALSE | G17: =IF(COUNTIF($B:$B,B17)=1,"Unique","Duplicate") -> Unique | H17: =IF(ISNUMBER(SEARCH("HD",D17)), IF(COUNTIF($D:$D,SUBSTITUTE(D17," HD",""))>0,"Has non-HD match","HD only"), IF(COUNTIF($D:$D,D17&" HD")>0,"Has HD match","Non-HD only") ) -> Non-HD only | I17: =IFERROR(LOOKUP(2,1/(ISNUMBER(SEARCH(Sheet1!$A$2:$A$100,B17))),Sheet1!$A$2:$A$100),"") -> AandE | J17: =LEFT(B17,FIND(" ",B17&" ")-1) -> AAndE.us
B18: ABC (KGO) San Francisco, CA (7).us | C18: Y | D18: A | E18: 85 | F18: FALSE | G18: =IF(COUNTIF($B:$B,B18)=1,"Unique","Duplicate") -> Unique | H18: =IF(ISNUMBER(SEARCH("HD",D18)), IF(COUNTIF($D:$D,SUBSTITUTE(D18," HD",""))>0,"Has non-HD match","HD only"), IF(COUNTIF($D:$D,D18&" HD")>0,"Has HD match","Non-HD only") ) -> Non-HD only | I18: =IFERROR(LOOKUP(2,1/(ISNUMBER(SEARCH(Sheet1!$A$2:$A$100,B18))),Sheet1!$A$2:$A$100),"") -> ABC | J18: =LEFT(B18,FIND(" ",B18&" ")-1) -> ABC
B19: ABC (WKBW) Buffalo, NY.ca | C19: Y | D19: A | E19: 64 | F19: FALSE | G19: =IF(COUNTIF($B:$B,B19)=1,"Unique","Duplicate") -> Unique | H19: =IF(ISNUMBER(SEARCH("HD",D19)), IF(COUNTIF($D:$D,SUBSTITUTE(D19," HD",""))>0,"Has non-HD match","HD only"), IF(COUNTIF($D:$D,D19&" HD")>0,"Has HD match","Non-HD only") ) -> Non-HD only | I19: =IFERROR(LOOKUP(2,1/(ISNUMBER(SEARCH(Sheet1!$A$2:$A$100,B19))),Sheet1!$A$2:$A$100),"") -> ABC | J19: =LEFT(B19,FIND(" ",B19&" ")-1) -> ABC
B20: Animal Planet US - West (253).us | C20: Y | D20: A | E20: 78 | F20: FALSE | G20: =IF(COUNTIF($B:$B,B20)=1,"Unique","Duplicate") -> Unique | H20: =IF(ISNUMBER(SEARCH("HD",D20)), IF(COUNTIF($D:$D,SUBSTITUTE(D20," HD",""))>0,"Has non-HD match","HD only"), IF(COUNTIF($D:$D,D20&" HD")>0,"Has HD match","Non-HD only") ) -> Non-HD only | I20: =IFERROR(LOOKUP(2,1/(ISNUMBER(SEARCH(Sheet1!$A$2:$A$100,B20))),Sheet1!$A$2:$A$100),"") -> Animal | J20: =LEFT(B20,FIND(" ",B20&" ")-1) -> Animal
B21: Animal Planet.uk | C21: Y | D21: A | E21: 64 | F21: FALSE | G21: =IF(COUNTIF($B:$B,B21)=1,"Unique","Duplicate") -> Unique | H21: =IF(ISNUMBER(SEARCH("HD",D21)), IF(COUNTIF($D:$D,SUBSTITUTE(D21," HD",""))>0,"Has non-HD match","HD only"), IF(COUNTIF($D:$D,D21&" HD")>0,"Has HD match","Non-HD only") ) -> Non-HD only | I21: =IFERROR(LOOKUP(2,1/(ISNUMBER(SEARCH(Sheet1!$A$2:$A$100,B21))),Sheet1!$A$2:$A$100),"") -> Animal | J21: =LEFT(B21,FIND(" ",B21&" ")-1) -> Animal
B22: Animal Planet.us | C22: Y | D22: A | E22: 73 | F22: FALSE | G22: =IF(COUNTIF($B:$B,B22)=1,"Unique","Duplicate") -> Unique | H22: =IF(ISNUMBER(SEARCH("HD",D22)), IF(COUNTIF($D:$D,SUBSTITUTE(D22," HD",""))>0,"Has non-HD match","HD only"), IF(COUNTIF($D:$D,D22&" HD")>0,"Has HD match","Non-HD only") ) -> Non-HD only | I22: =IFERROR(LOOKUP(2,1/(ISNUMBER(SEARCH(Sheet1!$A$2:$A$100,B22))),Sheet1!$A$2:$A$100),"") -> Animal | J22: =LEFT(B22,FIND(" ",B22&" ")-1) -> Animal
B23: Animal Plnt+1.uk | C23: Y | D23: A | E23: 64 | F23: FALSE | G23: =IF(COUNTIF($B:$B,B23)=1,"Unique","Duplicate") -> Unique | H23: =IF(ISNUMBER(SEARCH("HD",D23)), IF(COUNTIF($D:$D,SUBSTITUTE(D23," HD",""))>0,"Has non-HD match","HD only"), IF(COUNTIF($D:$D,D23&" HD")>0,"Has HD match","Non-HD only") ) -> Non-HD only | I23: =IFERROR(LOOKUP(2,1/(ISNUMBER(SEARCH(Sheet1!$A$2:$A$100,B23))),Sheet1!$A$2:$A$100),"") -> Animal | J23: =LEFT(B23,FIND(" ",B23&" ")-1) -> Animal
B24: Brit Asia TV.uk | C24: Y | D24: B | E24: 0 | F24: TRUE | G24: =IF(COUNTIF($B:$B,B24)=1,"Unique","Duplicate") -> Unique | H24: =IF(ISNUMBER(SEARCH("HD",D24)), IF(COUNTIF($D:$D,SUBSTITUTE(D24," HD",""))>0,"Has non-HD match","HD only"), IF(COUNTIF($D:$D,D24&" HD")>0,"Has HD match","Non-HD only") ) -> Non-HD only | I24: =IFERROR(LOOKUP(2,1/(ISNUMBER(SEARCH(Sheet1!$A$2:$A$100,B24))),Sheet1!$A$2:$A$100),"") -> 0 | J24: =LEFT(B24,FIND(" ",B24&" ")-1) -> Brit
B25: Action / SHA.au | C25: Y | D25: A | E25: 0 | F25: FALSE | G25: =IF(COUNTIF($B:$B,B25)=1,"Unique","Duplicate") -> Unique | H25: =IF(ISNUMBER(SEARCH("HD",D25)), IF(COUNTIF($D:$D,SUBSTITUTE(D25," HD",""))>0,"Has non-HD match","HD only"), IF(COUNTIF($D:$D,D25&" HD")>0,"Has HD match","Non-HD only") ) -> Non-HD only | I25: =IFERROR(LOOKUP(2,1/(ISNUMBER(SEARCH(Sheet1!$A$2:$A$100,B25))),Sheet1!$A$2:$A$100),"") -> iON | J25: =LEFT(B25,FIND(" ",B25&" ")-1) -> Action
B26: Action MAX.us | C26: Y | D26: A | E26: 43 | F26: FALSE | G26: =IF(COUNTIF($B:$B,B26)=1,"Unique","Duplicate") -> Unique | H26: =IF(ISNUMBER(SEARCH("HD",D26)), IF(COUNTIF($D:$D,SUBSTITUTE(D26," HD",""))>0,"Has non-HD match","HD only"), IF(COUNTIF($D:$D,D26&" HD")>0,"Has HD match","Non-HD only") ) -> Non-HD only | I26: =IFERROR(LOOKUP(2,1/(ISNUMBER(SEARCH(Sheet1!$A$2:$A$100,B26))),Sheet1!$A$2:$A$100),"") -> Max | J26: =LEFT(B26,FIND(" ",B26&" ")-1) -> Action
B27: Action SHA.au | C27: Y | D27: A | E27: 0 | F27: FALSE | G27: =IF(COUNTIF($B:$B,B27)=1,"Unique","Duplicate") -> Unique | H27: =IF(ISNUMBER(SEARCH("HD",D27)), IF(COUNTIF($D:$D,SUBSTITUTE(D27," HD",""))>0,"Has non-HD match","HD only"), IF(COUNTIF($D:$D,D27&" HD")>0,"Has HD match","Non-HD only") ) -> Non-HD only | I27: =IFERROR(LOOKUP(2,1/(ISNUMBER(SEARCH(Sheet1!$A$2:$A$100,B27))),Sheet1!$A$2:$A$100),"") -> iON | J27: =LEFT(B27,FIND(" ",B27&" ")-1) -> Action
... B43: Citytv Toronto.ca | C43: Y | D43: C | E43: 59 | F43: FALSE | G43: =IF(COUNTIF($B:$B,B43)=1,"Unique","Duplicate") -> Unique | H43: =IF(ISNUMBER(SEARCH("HD",D43)), IF(COUNTIF($D:$D,SUBSTITUTE(D43," HD",""))>0,"Has non-HD match","HD only"), IF(COUNTIF($D:$D,D43&" HD")>0,"Has HD match","Non-HD only") ) -> Non-HD only | I43: =IFERROR(LOOKUP(2,1/(ISNUMBER(SEARCH(Sheet1!$A$2:$A$100,B43))),Sheet1!$A$2:$A$100),"") -> Citytv | J43: =LEFT(B43,FIND(" ",B43&" ")-1) -> Citytv
A44: open-epg-au.xml | B44: CNN (202).us | C44: Y | D44: C | E44: 70 | F44: FALSE | G44: =IF(COUNTIF($B:$B,B44)=1,"Unique","Duplicate") -> Unique | H44: =IF(ISNUMBER(SEARCH("HD",D44)), IF(COUNTIF($D:$D,SUBSTITUTE(D44," HD",""))>0,"Has non-HD match","HD only"), IF(COUNTIF($D:$D,D44&" HD")>0,"Has HD match","Non-HD only") ) -> Non-HD only | I44: =IFERROR(LOOKUP(2,1/(ISNUMBER(SEARCH(Sheet1!$A$2:$A$100,B44))),Sheet1!$A$2:$A$100),"") -> CNN | J44: =LEFT(B44,FIND(" ",B44&" ")-1) -> CNN
B45: CNN / CNN.au | C45: Y | D45: C | E45: 74 | F45: FALSE | G45: =IF(COUNTIF($B:$B,B45)=1,"Unique","Duplicate") -> Unique | H45: =IF(ISNUMBER(SEARCH("HD",D45)), IF(COUNTIF($D:$D,SUBSTITUTE(D45," HD",""))>0,"Has non-HD match","HD only"), IF(COUNTIF($D:$D,D45&" HD")>0,"Has HD match","Non-HD only") ) -> Non-HD only | I45: =IFERROR(LOOKUP(2,1/(ISNUMBER(SEARCH(Sheet1!$A$2:$A$100,B45))),Sheet1!$A$2:$A$100),"") -> CNN | J45: =LEFT(B45,FIND(" ",B45&" ")-1) -> CNN
B46: CNN CNN.au | C46: Y | D46: C | E46: 72 | F46: FALSE | G46: =IF(COUNTIF($B:$B,B46)=1,"Unique","Duplicate") -> Unique | H46: =IF(ISNUMBER(SEARCH("HD",D46)), IF(COUNTIF($D:$D,SUBSTITUTE(D46," HD",""))>0,"Has non-HD match","HD only"), IF(COUNTIF($D:$D,D46&" HD")>0,"Has HD match","Non-HD only") ) -> Non-HD only | I46: =IFERROR(LOOKUP(2,1/(ISNUMBER(SEARCH(Sheet1!$A$2:$A$100,B46))),Sheet1!$A$2:$A$100),"") -> CNN | J46: =LEFT(B46,FIND(" ",B46&" ")-1) -> CNN
B47: CNN.ca | C47: Y | D47: C | E47: 151 | F47: FALSE | G47: =IF(COUNTIF($B:$B,B47)=1,"Unique","Duplicate") -> Unique | H47: =IF(ISNUMBER(SEARCH("HD",D47)), IF(COUNTIF($D:$D,SUBSTITUTE(D47," HD",""))>0,"Has non-HD match","HD only"), IF(COUNTIF($D:$D,D47&" HD")>0,"Has HD match","Non-HD only") ) -> Non-HD only | I47: =IFERROR(LOOKUP(2,1/(ISNUMBER(SEARCH(Sheet1!$A$2:$A$100,B47))),Sheet1!$A$2:$A$100),"") -> CNN | J47: =LEFT(B47,FIND(" ",B47&" ")-1) -> CNN.ca
B48: CNN.us | C48: Y | D48: C | E48: 72 | F48: FALSE | G48: =IF(COUNTIF($B:$B,B48)=1,"Unique","Duplicate") -> Unique | H48: =IF(ISNUMBER(SEARCH("HD",D48)), IF(COUNTIF($D:$D,SUBSTITUTE(D48," HD",""))>0,"Has non-HD match","HD only"), IF(COUNTIF($D:$D,D48&" HD")>0,"Has HD match","Non-HD only") ) -> Non-HD only | I48: =IFERROR(LOOKUP(2,1/(ISNUMBER(SEARCH(Sheet1!$A$2:$A$100,B48))),Sheet1!$A$2:$A$100),"") -> CNN | J48: =LEFT(B48,FIND(" ",B48&" ")-1) -> CNN.us
B49: Haunt TV / HTV.au | C49: Y | D49: H | E49: 78 | F49: FALSE | G49: =IF(COUNTIF($B:$B,B49)=1,"Unique","Duplicate") -> Unique | H49: =IF(ISNUMBER(SEARCH("HD",D49)), IF(COUNTIF($D:$D,SUBSTITUTE(D49," HD",""))>0,"Has non-HD match","HD only"), IF(COUNTIF($D:$D,D49&" HD")>0,"Has HD match","Non-HD only") ) -> Non-HD only | I49: =IFERROR(LOOKUP(2,1/(ISNUMBER(SEARCH(Sheet1!$A$2:$A$100,B49))),Sheet1!$A$2:$A$100),"") -> 0 | J49: =LEFT(B49,FIND(" ",B49&" ")-1) -> Haunt
B50: Haunt TV HTV.au | C50: Y | D50: H | E50: 76 | F50: FALSE | G50: =IF(COUNTIF($B:$B,B50)=1,"Unique","Duplicate") -> Unique | H50: =IF(ISNUMBER(SEARCH("HD",D50)), IF(COUNTIF($D:$D,SUBSTITUTE(D50," HD",""))>0,"Has non-HD match","HD only"), IF(COUNTIF($D:$D,D50&" HD")>0,"Has HD match","Non-HD only") ) -> Non-HD only | I50: =IFERROR(LOOKUP(2,1/(ISNUMBER(SEARCH(Sheet1!$A$2:$A$100,B50))),Sheet1!$A$2:$A$100),"") -> 0 | J50: =LEFT(B50,FIND(" ",B50&" ")-1) -> Haunt
B51: HauntTV.uk | C51: Y | D51: H | E51: 65 | F51: FALSE | G51: =IF(COUNTIF($B:$B,B51)=1,"Unique","Duplicate") -> Unique | H51: =IF(ISNUMBER(SEARCH("HD",D51)), IF(COUNTIF($D:$D,SUBSTITUTE(D51," HD",""))>0,"Has non-HD match","HD only"), IF(COUNTIF($D:$D,D51&" HD")>0,"Has HD match","Non-HD only") ) -> Non-HD only | I51: =IFERROR(LOOKUP(2,1/(ISNUMBER(SEARCH(Sheet1!$A$2:$A$100,B51))),Sheet1!$A$2:$A$100),"") -> 0 | J51: =LEFT(B51,FIND(" ",B51&" ")-1) -> HauntTV.uk
B52: ITV1 +1 London.uk | C52: Y | D52: I | E52: 50 | F52: FALSE | G52: =IF(COUNTIF($B:$B,B52)=1,"Unique","Duplicate") -> Unique | H52: =IF(ISNUMBER(SEARCH("HD",D52)), IF(COUNTIF($D:$D,SUBSTITUTE(D52," HD",""))>0,"Has non-HD match","HD only"), IF(COUNTIF($D:$D,D52&" HD")>0,"Has HD match","Non-HD only") ) -> Non-HD only | I52: =IFERROR(LOOKUP(2,1/(ISNUMBER(SEARCH(Sheet1!$A$2:$A$100,B52))),Sheet1!$A$2:$A$100),"") -> ITV | J52: =LEFT(B52,FIND(" ",B52&" ")-1) -> ITV1
B53: ITV1 +1.uk | C53: Y | D53: I | E53: 74 | F53: FALSE | G53: =IF(COUNTIF($B:$B,B53)=1,"Unique","Duplicate") -> Unique | H53: =IF(ISNUMBER(SEARCH("HD",D53)), IF(COUNTIF($D:$D,SUBSTITUTE(D53," HD",""))>0,"Has non-HD match","HD only"), IF(COUNTIF($D:$D,D53&" HD")>0,"Has HD match","Non-HD only") ) -> Non-HD only | I53: =IFERROR(LOOKUP(2,1/(ISNUMBER(SEARCH(Sheet1!$A$2:$A$100,B53))),Sheet1!$A$2:$A$100),"") -> ITV | J53: =LEFT(B53,FIND(" ",B53&" ")-1) -> ITV1
B54: ITV1 London.uk | C54: Y | D54: I | E54: 97 | F54: FALSE | G54: =IF(COUNTIF($B:$B,B54)=1,"Unique","Duplicate") -> Unique | H54: =IF(ISNUMBER(SEARCH("HD",D54)), IF(COUNTIF($D:$D,SUBSTITUTE(D54," HD",""))>0,"Has non-HD match","HD only"), IF(COUNTIF($D:$D,D54&" HD")>0,"Has HD match","Non-HD only") ) -> Non-HD only | I54: =IFERROR(LOOKUP(2,1/(ISNUMBER(SEARCH(Sheet1!$A$2:$A$100,B54))),Sheet1!$A$2:$A$100),"") -> ITV | J54: =LEFT(B54,FIND(" ",B54&" ")-1) -> ITV1
B55: ITV1+1.uk | C55: Y | D55: I | E55: 52 | F55: FALSE | G55: =IF(COUNTIF($B:$B,B55)=1,"Unique","Duplicate") -> Unique | H55: =IF(ISNUMBER(SEARCH("HD",D55)), IF(COUNTIF($D:$D,SUBSTITUTE(D55," HD",""))>0,"Has non-HD match","HD only"), IF(COUNTIF($D:$D,D55&" HD")>0,"Has HD match","Non-HD only") ) -> Non-HD only | I55: =IFERROR(LOOKUP(2,1/(ISNUMBER(SEARCH(Sheet1!$A$2:$A$100,B55))),Sheet1!$A$2:$A$100),"") -> ITV | J55: =LEFT(B55,FIND(" ",B55&" ")-1) -> ITV1+1.uk
...

Sheet Sheet2
A1: AandE | B1: x
A2: ABC | B2: x
A3: AMC | B3: x
A4: Animal | B4: x
A5: BBC | B5: x
A6: Bravo | B6: x
A7: BritBox | B7: x
A8: CMT | B8: x
A9: CNBC | B9: x
A10: CNN | B10: x
A11: Cooking | B11: x
A12: Cottage | B12: x
... A64: Warner | B64: x
A65: (KMTP)
A66: 00s
A67: 10
A68: 10.au
A69: 11.au
A70: 2010s
A71: 2M
A72: 4
A73: 40
A74: 40+.uk
A75: 48
A76: 4Music.uk
... A1978: Zoomoo.us

Sheet Sheet1
A1: Networks
A3: AandE
A4: ABC
A5: ABC News
A6: AMC
A7: Animal
A8: BBC
A9: BBC Four
A10: BBC One
A11: BBC Three
A12: BBC Two
A13: Bell
... A124: YTV
